Workbook
Name מחוז_ענף_כלכלי__סדר: מחוז_ענף_כלכלי__סדר!$A$1:$E$169
Name מחוז_ענף_כלכלי_2_ספרות: מחוז_ענף_כלכלי_2_ספרות!$A$1:$D$594
Name מחוז_ענף_כלכלי_3_ספרות: מחוז_ענף_כלכלי_3_ספרות!$A$1:$E$73
Name רשויות_ענף_כלכלי__2ספרות_: רשויות_ענף_כלכלי__2ספרות_!$A$1:$E$746
Name רשויות_ענף_כלכלי__3ספרות_: רשויות_ענף_כלכלי__3ספרות_!$A$1:$D$86
Name רשויות_ענף_כלכלי__סדר_: רשויות_ענף_כלכלי__סדר_!$A$1:$D$316

Sheet מידע נילווה
A9: תאריך הפקה:
A11: יחידה בלמ"ס שהפיקה את הנתונים: | B11: אגף מיקרו כלכלה
A13: שם המפיק: | B13: אורלי פורמן
A15: לשאלות ובירורים נא לפנות ליחידת המידע: | B15: 02-6592666 או
B16: info@cbs.gov.il
A18: סוג ההפקה: | B18: עיבוד מיוחד מורכב
A20: מקורות הנתונים:
A21: - | B21: קובצי הכנסה מנהליים
B22: עבור השנים 2018-2022
A23: סימנים מיוחדים:
A24: ריק | B24: חוסר מקרים
A25: * | B25: ללא ענף כלכלי
A26: הסבר נוסף:
A27: שכר חודשי ממוצע | B27: חושב ע"י חלוקת השכר השנתי במספר חודשי העבודה, רק הכנסה משכר
A28: שכיר | B28: כל בעלי ההכנסה משכר במהלך השנה, גם אם היתה לו הכנסה עסקית
A29: ענף כלכלי | B29: ענף כלכלי של המשרה המניבה יותר במהלך השנה
B30: לעניין קיבוץ ענפי הכלכלה בשתי ספרות בהתאם לבקשה- הוצג הענף באופנות הראשונה על פיה אוחדו

Sheet רשויות_ענף_כלכלי__3ספרות_
A1: ShemMaamadMuniOMoeza | B1: ענף כלכלי | C1: מספר שכירים | D1: שכר חודשי ממוצי
A2: בוקעאתא | B2: 857 | C2: 218 | D2: 13360.924
A3: ג'ש (גוש חלב) | B3: 852 | C3: 16 | D3: 15801.911
A4: ג'ש (גוש חלב) | B4: 854 | C4: 11 | D4: 15867.083
A5: ג'ש (גוש חלב) | B5: 857 | C5: 86 | D5: 14848.946
A6: גולן | B6: 850 | C6: 11 | D6: 5945.223
A7: גולן | B7: 851 | C7: 52 | D7: 9488.4871
A8: גולן | B8: 852 | C8: 307 | D8: 14508.5
A9: גולן | B9: 853 | C9: 52 | D9: 8023.3834
A10: גולן | B10: 854 | C10: 116 | D10: 10710.802
A11: גולן | B11: 855 | C11: 34 | D11: 11075.198
A12: גולן | B12: 856 | C12: 40 | D12: 9154.8053
A13: גולן | B13: 857 | C13: 979 | D13: 12026.86
... A86: ראש פינה | B86: 857 | C86: 95 | D86: 11898.867

Sheet רשויות_ענף_כלכלי__2ספרות_
A1: ShemMaamadMuniOMoeza | B1: ענף כלכלי | C1: שם ענף | D1: מספר שכירים | E1: שכר חודשי ממוצי | J1: סדר | K1: ענף ראשי | L1: תיאור
A2: בוקעאתא | B2: 1 | C2: =INDEX(L:L,MATCH(B2,K:K,0)) -> גידולים צמחיים | D2: 263 | E2: 5828.4334 | J2: A | L2: חקלאות, ייעור ודיג
A3: בוקעאתא | B3: 4 | C3: =INDEX(L:L,MATCH(B3,K:K,0)) -> גידול בעלי חיים, ציד ופעילויות נלוות | D3: 41 | E3: 6468.1012 | K3: 1 | L3: גידולים צמחיים
A4: בוקעאתא | B4: 10 | C4: =INDEX(L:L,MATCH(B4,K:K,0)) -> ייצור מוצרי מזון | D4: 21 | E4: 10089.296 | K4: 2 | L4: ייעור וכריתת עצים
A5: בוקעאתא | B5: 11 | C5: =INDEX(L:L,MATCH(B5,K:K,0)) -> ייצור משקאות | D5: 32 | E5: 12219.862 | K5: 3 | L5: דיג וחקלאות מים
A6: בוקעאתא | B6: 13 | C6: =INDEX(L:L,MATCH(B6,K:K,0)) -> ייצור טקסטיל | D6: 15 | E6: 6051.9078 | K6: 4 | L6: גידול בעלי חיים, ציד ופעילויות נלוות
A7: בוקעאתא | B7: 20 | C7: =INDEX(L:L,MATCH(B7,K:K,0)) -> ייצור כימיקלים ומוצריהם | D7: 30 | E7: 11296.285 | J7: B | L7: כרייה וחציבה
A8: בוקעאתא | B8: 22 | C8: =INDEX(L:L,MATCH(B8,K:K,0)) -> ייצור מוצרי גומי ופלסטיק | D8: 23 | E8: 8583.6463 | K8: 5 | L8: כריית פחם ופחם חום
A9: בוקעאתא | B9: 23 | C9: =INDEX(L:L,MATCH(B9,K:K,0)) -> ייצור מוצרים אחרים על בסיס מינרלים אל-מתכתיים | D9: 25 | E9: 12565.408 | K9: 6 | L9: הפקת נפט גולמי וגז טבעי
A10: בוקעאתא | B10: 32 | C10: =INDEX(L:L,MATCH(B10,K:K,0)) -> ענפי ייצור אחרים | D10: 21 | E10: 9686.6691 | K10: 7 | L10: כריית עפרות מתכת
A11: בוקעאתא | B11: 33 | C11: =INDEX(L:L,MATCH(B11,K:K,0)) -> תיקון, תחזוקה והתקנה של מכונות וציוד | D11: 13 | E11: 4182.6472 | K11: 8 | L11: סוגים אחרים של כרייה וחציבה
A12: בוקעאתא | B12: 41 | C12: =INDEX(L:L,MATCH(B12,K:K,0)) -> בניית מבנים ובניינים | D12: 225 | E12: 7612.2049 | K12: 9 | L12: פעילויות עזר לכרייה
A13: בוקעאתא | B13: 42 | C13: =INDEX(L:L,MATCH(B13,K:K,0)) -> עבודות הנדסה אזרחית | D13: 260 | E13: 8543.1291 | J13: C | L13: תעשייה
A14: בוקעאתא | B14: 43 | C14: =INDEX(L:L,MATCH(B14,K:K,0)) -> עבודות בנייה מיוחדות | D14: 124 | E14: 6924.5629 | K14: 10 | L14: ייצור מוצרי מזון
A15: בוקעאתא | B15: 45 | C15: =INDEX(L:L,MATCH(B15,K:K,0)) -> מסחר סיטוני וקמעוני בכלי רכב מנועיים ובאופנועים ותיקונם | D15: 31 | E15: 7414.9551 | K15: 11 | L15: ייצור משקאות
A16: בוקעאתא | B16: 46 | C16: =INDEX(L:L,MATCH(B16,K:K,0)) -> מסחר סיטוני, פרט לכלי רכב מנועיים ולאופנועים | D16: 60 | E16: 7235.7007 | K16: 12 | L16: ייצור מוצרי טבק
A17: בוקעאתא | B17: 47 | C17: =INDEX(L:L,MATCH(B17,K:K,0)) -> מכירה קמעונית, פרט לכלי רכב מנועיים ולאופנועים | D17: 213 | E17: 5013.9065 | K17: 13 | L17: ייצור טקסטיל
A18: בוקעאתא | B18: 49 | C18: =INDEX(L:L,MATCH(B18,K:K,0)) -> הובלה יבשתית והובלה באמצעות קווי צינורות | D18: 75 | E18: 6523.1304 | K18: 14 | L18: ייצור מוצרי הלבשה
A19: בוקעאתא | B19: 52 | C19: =INDEX(L:L,MATCH(B19,K:K,0)) -> אחסנה ושירותי עזר לתחבורה | D19: 16 | E19: 6877.3133 | K19: 15 | L19: ייצור ועיבוד של מוצרי עור ושל אביזרים נלווים
A20: בוקעאתא | B20: 55 | C20: =INDEX(L:L,MATCH(B20,K:K,0)) -> שירותי אירוח | D20: 201 | E20: 5684.6668 | K20: 16 | L20: ייצור מוצרי עץ ומוצרי עץ ושעם, פרט לרהיטים; ייצור מוצרי קש ומוצרים מחומרי קליעה
A21: בוקעאתא | B21: 56 | C21: =INDEX(L:L,MATCH(B21,K:K,0)) -> שירותי מזון ומשקאות | D21: 43 | E21: 4390.3779 | K21: 17 | L21: ייצור נייר ומוצריו
A22: בוקעאתא | B22: 62 | C22: =INDEX(L:L,MATCH(B22,K:K,0)) -> תכנות מחשבים, ייעוץ בתחום המחשבים ושירותים נלווים אחרים | D22: 28 | E22: 14349.075 | K22: 18 | L22: הדפסה ושכפול של חומר תקשורתי מוקלט
A23: בוקעאתא | B23: 64 | C23: =INDEX(L:L,MATCH(B23,K:K,0)) -> שירותים פיננסיים, פרט לביטוח ולקרנות פנסיה | D23: 16 | E23: 9562.9688 | K23: 19 | L23: ייצור מוצרי נפט מזוקק
A24: בוקעאתא | B24: 68 | C24: =INDEX(L:L,MATCH(B24,K:K,0)) -> פעילויות בנדל"ן | D24: 22 | E24: 9488.7939 | K24: 20 | L24: ייצור כימיקלים ומוצריהם
A25: בוקעאתא | B25: 69 | C25: =INDEX(L:L,MATCH(B25,K:K,0)) -> שירותים משפטיים ושירותי חשבונאות | D25: 12 | E25: 6434.2083 | K25: 21 | L25: ייצור תרופות, כולל תרופות הומאופתיות
... A38: ג'ש (גוש חלב) | B38: 1 | C38: =INDEX(L:L,MATCH(B38,K:K,0)) -> גידולים צמחיים | D38: 95 | E38: 8814.347 | K38: 34 | L38: עיבוד יהלומים
A39: ג'ש (גוש חלב) | B39: 10 | C39: =INDEX(L:L,MATCH(B39,K:K,0)) -> ייצור מוצרי מזון | D39: 52 | E39: 10013.378 | J39: D | L39: אספקת חשמל, גז, קיטור ומיזוג אוויר
A40: ג'ש (גוש חלב) | B40: 20 | C40: =INDEX(L:L,MATCH(B40,K:K,0)) -> ייצור כימיקלים ומוצריהם | D40: 24 | E40: 9418.2285 | K40: 35 | L40: אספקת חשמל, גז, קיטור ומיזוג אוויר (קירור)
A41: ג'ש (גוש חלב) | B41: 22 | C41: =INDEX(L:L,MATCH(B41,K:K,0)) -> ייצור מוצרי גומי ופלסטיק | D41: 17 | E41: 11168.906 | J41: E | L41: אספקת מים; שירותי ביוב, טיפול באשפה ובפסולת ושירותי טיהור
A42: ג'ש (גוש חלב) | B42: 23 | C42: =INDEX(L:L,MATCH(B42,K:K,0)) -> ייצור מוצרים אחרים על בסיס מינרלים אל-מתכתיים | D42: 29 | E42: 14047.508 | K42: 36 | L42: אגירת מים, טיפול ואספקה
A43: ג'ש (גוש חלב) | B43: 27 | C43: =INDEX(L:L,MATCH(B43,K:K,0)) -> ייצור ציוד חשמלי | D43: 29 | E43: 9360.0386 | K43: 37 | L43: שירותי ביוב
A44: ג'ש (גוש חלב) | B44: 31 | C44: =INDEX(L:L,MATCH(B44,K:K,0)) -> ייצור רהיטים | D44: 16 | E44: 7420.7788 | K44: 38 | L44: איסוף, טיפול וסילוק של אשפה ופסולת; מחזור (והשבה) של חומרים
A45: ג'ש (גוש חלב) | B45: 32 | C45: =INDEX(L:L,MATCH(B45,K:K,0)) -> ענפי ייצור אחרים | D45: 96 | E45: 9992.3652 | K45: 39 | L45: שירותי טיהור ושירותים אחרים לטיפול בפסולת
A46: ג'ש (גוש חלב) | B46: 41 | C46: =INDEX(L:L,MATCH(B46,K:K,0)) -> בניית מבנים ובניינים | D46: 31 | E46: 7722.5494 | J46: סדר | K46: ענף ראשי | L46: תיאור
A47: ג'ש (גוש חלב) | B47: 42 | C47: =INDEX(L:L,MATCH(B47,K:K,0)) -> עבודות הנדסה אזרחית | D47: 20 | E47: 14438.492 | J47: F | L47: בינוי
A48: ג'ש (גוש חלב) | B48: 43 | C48: =INDEX(L:L,MATCH(B48,K:K,0)) -> עבודות בנייה מיוחדות | D48: 50 | E48: 7727.0518 | K48: 41 | L48: בניית מבנים ובניינים
A49: ג'ש (גוש חלב) | B49: 45 | C49: =INDEX(L:L,MATCH(B49,K:K,0)) -> מסחר סיטוני וקמעוני בכלי רכב מנועיים ובאופנועים ותיקונם | D49: 24 | E49: 8593.7503 | K49: 42 | L49: עבודות הנדסה אזרחית
A50: ג'ש (גוש חלב) | B50: 46 | C50: =INDEX(L:L,MATCH(B50,K:K,0)) -> מסחר סיטוני, פרט לכלי רכב מנועיים ולאופנועים | D50: 25 | E50: 10458.846 | K50: 43 | L50: עבודות בנייה מיוחדות
A51: ג'ש (גוש חלב) | B51: 47 | C51: =INDEX(L:L,MATCH(B51,K:K,0)) -> מכירה קמעונית, פרט לכלי רכב מנועיים ולאופנועים | D51: 116 | E51: 8981.9923 | J51: G | L51: מסחר סיטוני וקמעוני; תיקון כלי רכב מנועיים ואופנועים
A52: ג'ש (גוש חלב) | B52: 49 | C52: =INDEX(L:L,MATCH(B52,K:K,0)) -> הובלה יבשתית והובלה באמצעות קווי צינורות | D52: 32 | E52: 11753.071 | K52: 45 | L52: מסחר סיטוני וקמעוני בכלי רכב מנועיים ובאופנועים ותיקונם
...

Sheet פיבוט
A4: Row Labels | B4: Average of שכר חודשי ממוצי | C4: Sum of מספר שכירים
A5: הגליל העליון | B5: 13122.927 | C5: 8547
A6: Grand Total | B6: 13122.927 | C6: 8547

Sheet רשויות_ענף_כלכלי__סדר_
A1: ShemMaamadMuniOMoeza | B1: ענף כלכלי | C1: מספר שכירים | D1: שכר חודשי ממוצי | N1: ShemMaamadMuniOMoeza | O1: קצרין
A2: בוקעאתא | B2: * | C2: 34 | D2: 15437.083
A3: בוקעאתא | B3: A | C3: 304 | D3: 5914.7044 | M3: שם ענף | N3: Row Labels | O3: Sum of מספר שכירים | P3: Average of שכר חודשי ממוצי
A4: בוקעאתא | B4: C | C4: 209 | D4: 9482.7361 | N4: * | O4: 134 | P4: 18495.795
A5: בוקעאתא | B5: E | C5: 10 | D5: 12726.853 | M5: חקלאות, ייעור ודיג | N5: A | O5: 121 | P5: 7224.6458
A6: בוקעאתא | B6: F | C6: 609 | D6: 7869.6313 | M6: תעשייה | N6: C | O6: 664 | P6: 10505.584
A7: בוקעאתא | B7: G | C7: 304 | D7: 5697.2623 | M7: אספקת מים; שירותי ביוב, טיפול באשפה ובפסולת ושירותי טיהור | N7: E | O7: 11 | P7: 15036.551
A8: בוקעאתא | B8: H | C8: 91 | D8: 6585.4043 | M8: בינוי | N8: F | O8: 100 | P8: 10060.988
A9: בוקעאתא | B9: I | C9: 244 | D9: 5456.5749 | M9: מסחר סיטוני וקמעוני; תיקון כלי רכב מנועיים ואופנועים | N9: G | O9: 366 | P9: 7160.8033
A10: בוקעאתא | B10: J | C10: 36 | D10: 12609.04 | M10: שירותי תחבורה, אחסנה, דואר ובלדרות | N10: H | O10: 99 | P10: 9069.1325
A11: בוקעאתא | B11: K | C11: 16 | D11: 9562.9688 | M11: שירותי אירוח ואוכל | N11: I | O11: 394 | P11: 5948.9582
A12: בוקעאתא | B12: L | C12: 22 | D12: 9488.7939 | M12: מידע ותקשורת | N12: J | O12: 110 | P12: 16322.041
A13: בוקעאתא | B13: M | C13: 163 | D13: 7013.5367 | M13: שירותים פיננסיים ושירותי ביטוח | N13: K | O13: 43 | P13: 10698.006
A14: בוקעאתא | B14: N | C14: 179 | D14: 4063.8821 | M14: פעילויות בנדל"ן | N14: L | O14: 13 | P14: 7143.3333
A15: בוקעאתא | B15: O | C15: 146 | D15: 11637.596 | M15: שירותים מקצועיים, מדעיים וטכניים | N15: M | O15: 268 | P15: 10509.417
A16: בוקעאתא | B16: P | C16: 235 | D16: 13280.967 | M16: שירותי ניהול ותמיכה | N16: N | O16: 301 | P16: 6405.709
... A22: ג'ש (גוש חלב) | B22: C | C22: 287 | D22: 10683.526 | M22: אמנות, בידור ופנאי | N22: Grand Total | O22: 4069 | P22: 9500.5279
A23: ג'ש (גוש חלב) | B23: F | C23: 101 | D23: 9054.668 | M23: שירותים אחרים
A24: ג'ש (גוש חלב) | B24: G | C24: 165 | D24: 9149.2865 | M24: #N/A
A25: ג'ש (גוש חלב) | B25: H | C25: 38 | D25: 10737.705
A26: ג'ש (גוש חלב) | B26: I | C26: 115 | D26: 6385.226
A27: ג'ש (גוש חלב) | B27: J | C27: 30 | D27: 25598.272
A28: ג'ש (גוש חלב) | B28: K | C28: 24 | D28: 12804.956
A29: ג'ש (גוש חלב) | B29: M | C29: 97 | D29: 10958.159
A30: ג'ש (גוש חלב) | B30: N | C30: 98 | D30: 6979.3263
A31: ג'ש (גוש חלב) | B31: O | C31: 166 | D31: 15457.577
A32: ג'ש (גוש חלב) | B32: P | C32: 126 | D32: 14027.574
A33: ג'ש (גוש חלב) | B33: Q | C33: 176 | D33: 10190.069
A34: ג'ש (גוש חלב) | B34: R | C34: 20 | D34: 5643.9677
A35: ג'ש (גוש חלב) | B35: S | C35: 41 | D35: 9952.8496
A36: גולן | B36: * | C36: 407 | D36: 20226.219
... A280: קריית שמונה | B280: * | C280: 353 | D280: 18169.846
A281: קריית שמונה | B281: A | C281: 217 | D281: 7632.0344 | E281: 0
A282: קריית שמונה | B282: B | C282: 27 | D282: 17557.075 | E282: 0
A283: קריית שמונה | B283: C | C283: 2388 | D283: 11438.506 | E283: 0
A284: קריית שמונה | B284: E | C284: 58 | D284: 11999.708 | E284: 51
A285: קריית שמונה | B285: F | C285: 233 | D285: 10941.804 | E285: 175
A286: קריית שמונה | B286: G | C286: 1714 | D286: 8375.0523 | E286: 1481
A287: קריית שמונה | B287: H | C287: 361 | D287: 11323.354 | E287: -1353
A288: קריית שמונה | B288: I | C288: 1181 | D288: 5568.1956 | E288: 820
...

Sheet מחוז_ענף_כלכלי_3_ספרות
A1: CodMahozs | C1: ענף כלכלי | D1: מספר שכירים | E1: שכר חודשי ממוצי
A2: איוש | C2: 850 | D2: 4497 | E2: 5266.8586
A3: איוש | C3: 851 | D3: 7875 | E3: 7170.268
A4: איוש | C4: 852 | D4: 6291 | E4: 10350.296
A5: איוש | C5: 853 | D5: 652 | E5: 9090.5388
A6: איוש | C6: 854 | D6: 1199 | E6: 11845.445
A7: איוש | C7: 855 | D7: 2186 | E7: 11542.586
A8: איוש | C8: 856 | D8: 5204 | E8: 6577.5029
A9: איוש | C9: 857 | D9: 13718 | E9: 11301.596
A10: איוש | C10: 858 | D10: 243 | E10: 5772.6693
A11: דרום | C11: 850 | D11: 3851 | E11: 5557.2968
A12: דרום | C12: 851 | D12: 5658 | E12: 8011.5714
A13: דרום | C13: 852 | D13: 8180 | E13: 11235.42
... A73: תל אביב | C73: 858 | D73: 196 | E73: 7861.2731

Sheet מחוז_ענף_כלכלי_2_ספרות
A1: CodMahozs | B1: ענף כלכלי | C1: מספר שכירים | D1: שכר חודשי ממוצי
A2: איוש | B2: 1 | C2: 2263 | D2: 6652.1466
A3: איוש | B3: 2 | C3: 48 | D3: 26377.914
A4: איוש | B4: 3 | C4: 10 | D4: 8622.8088
A5: איוש | B5: 4 | C5: 218 | D5: 7231.0786
A6: איוש | B6: 8 | C6: 57 | D6: 19573.106
A7: איוש | B7: 10 | C7: 2244 | D7: 8616.7404
A8: איוש | B8: 11 | C8: 514 | D8: 7887.1989
A9: איוש | B9: 13 | C9: 268 | D9: 10840.44
A10: איוש | B10: 16 | C10: 136 | D10: 12856.683
A11: איוש | B11: 18 | C11: 363 | D11: 9737.2113
A12: איוש | B12: 20 | C12: 417 | D12: 15336.769
A13: איוש | B13: 21 | C13: 352 | D13: 20514.635
... A594: תל אביב | B594: 99 | C594: 594 | D594: 18552.256

Sheet מחוז_ענף_כלכלי__סדר
A1: CodMahozs | B1: ענף כלכלי | C1: ענף | D1: מספר שכירים | E1: שכר חודשי ממוצי
A2: איוש | B2: * | D2: 6087 | E2: 20201.097 | O2: Average of שכר חודשי ממוצי | P2: Column Labels
A3: איוש | B3: A | C3: =VLOOKUP(B3,רשויות_ענף_כלכלי__2ספרות_!$J$2:$L$115,3,FALSE) -> חקלאות, ייעור ודיג | D3: 2539 | E3: 7082.5328 | O3: ענף כלכלי | P3: איוש | Q3: דרום | R3: חיפה | S3: ירושלים | T3: מחוז צפון ללא | U3: מרכז | V3: נפות צפת וגולן | W3: תל אביב | X3: Grand Total
A4: איוש | B4: B | C4: =VLOOKUP(B4,רשויות_ענף_כלכלי__2ספרות_!$J$2:$L$115,3,FALSE) -> כרייה וחציבה | D4: 66 | E4: 22314.781 | O4: אמנות, בידור ופנאי | P4: 5975.5194 | Q4: 7019.4053 | R4: 6135.3687 | S4: 7273.3309 | T4: 6303.1238 | U4: 6581.5361 | V4: 6768.9293 | W4: 8300.5439 | X4: 6794.7197
A5: איוש | B5: C | C5: =VLOOKUP(B5,רשויות_ענף_כלכלי__2ספרות_!$J$2:$L$115,3,FALSE) -> תעשייה | D5: 10432 | E5: 15448.778 | O5: אספקת חשמל, גז, קיטור ומיזוג אוויר | P5: 27878.831 | Q5: 25753.132 | R5: 30523.103 | S5: 22878.2 | T5: 28054.891 | U5: 32673.112 | V5: 22344.183 | W5: 30032.855 | X5: 27517.288
A6: איוש | B6: D | C6: =VLOOKUP(B6,רשויות_ענף_כלכלי__2ספרות_!$J$2:$L$115,3,FALSE) -> אספקת חשמל, גז, קיטור ומיזוג אוויר | D6: 349 | E6: 27878.831 | O6: אספקת מים; שירותי ביוב, טיפול באשפה ובפסולת ושירותי טיהור | P6: 16191.56 | Q6: 13878.68 | R6: 13794.101 | S6: 10211.798 | T6: 12162.725 | U6: 15244.746 | V6: 15086.192 | W6: 15550.526 | X6: 14015.041
A7: איוש | B7: E | C7: =VLOOKUP(B7,רשויות_ענף_כלכלי__2ספרות_!$J$2:$L$115,3,FALSE) -> אספקת מים; שירותי ביוב, טיפול באשפה ובפסולת ושירותי טיהור | D7: 315 | E7: 16191.56 | O7: ארגונים וגופים חוץ-מדינתיים | P7: 22218.944 | Q7: 17448.402 | R7: 16382.312 | S7: 19020.573 | T7: 15987.165 | U7: 19083.976 | V7: 13491.191 | W7: 18552.256 | X7: 17773.102
A8: איוש | B8: F | C8: =VLOOKUP(B8,רשויות_ענף_כלכלי__2ספרות_!$J$2:$L$115,3,FALSE) -> בינוי | D8: 7167 | E8: 13093.008 | O8: בינוי | P8: 13093.008 | Q8: 11371.466 | R8: 10656.475 | S8: 8916.2721 | T8: 8219.2359 | U8: 14328.221 | V8: 8594.0469 | W8: 15388.598 | X8: 11320.915
A9: איוש | B9: G | C9: =VLOOKUP(B9,רשויות_ענף_כלכלי__2ספרות_!$J$2:$L$115,3,FALSE) -> מסחר סיטוני וקמעוני; תיקון כלי רכב מנועיים ואופנועים | D9: 21112 | E9: 8465.3974 | O9: חינוך | P9: 9107.699 | Q9: 10663.385 | R9: 11241.574 | S9: 8847.2289 | T9: 11295.912 | U9: 11072.18 | V9: 10469.979 | W9: 9646.853 | X9: 10293.101
A10: איוש | B10: H | C10: =VLOOKUP(B10,רשויות_ענף_כלכלי__2ספרות_!$J$2:$L$115,3,FALSE) -> שירותי תחבורה, אחסנה, דואר ובלדרות | D10: 4361 | E10: 12440.864 | O10: חקלאות, ייעור ודיג | P10: 7082.5328 | Q10: 14259.207 | R10: 14174.928 | S10: 13911.928 | T10: 13484.72 | U10: 15749.701 | V10: 13532.036 | W10: 15186.067 | X10: 13845.314
A11: איוש | B11: I | C11: =VLOOKUP(B11,רשויות_ענף_כלכלי__2ספרות_!$J$2:$L$115,3,FALSE) -> שירותי אירוח ואוכל | D11: 9697 | E11: 4588.2312 | O11: כרייה וחציבה | P11: 22314.781 | Q11: 29879.927 | R11: 21114.719 | S11: 16066.058 | T11: 16912.907 | U11: 26195.455 | V11: 17832.677 | W11: 36565.012 | X11: 23360.192
A12: איוש | B12: J | C12: =VLOOKUP(B12,רשויות_ענף_כלכלי__2ספרות_!$J$2:$L$115,3,FALSE) -> מידע ותקשורת | D12: 10280 | E12: 21745.864 | O12: מידע ותקשורת | P12: 21745.864 | Q12: 19665.653 | R12: 24356.973 | S12: 19873.732 | T12: 21035.312 | U12: 29126.391 | V12: 18955.911 | W12: 30425.284 | X12: 23148.14
A13: איוש | B13: K | C13: =VLOOKUP(B13,רשויות_ענף_כלכלי__2ספרות_!$J$2:$L$115,3,FALSE) -> שירותים פיננסיים ושירותי ביטוח | D13: 4176 | E13: 19166.415 | O13: מינהל מקומי, מינהל ציבורי וביטחון; ביטוח לאומי חובה | P13: 10630.492 | Q13: 11536.024 | R13: 12899.629 | S13: 13510.56 | T13: 12177.888 | U13: 12871.757 | V13: 11608.868 | W13: 13873.637 | X13: 12388.607
A14: איוש | B14: L | C14: =VLOOKUP(B14,רשויות_ענף_כלכלי__2ספרות_!$J$2:$L$115,3,FALSE) -> פעילויות בנדל"ן | D14: 1463 | E14: 11552.952 | O14: מסחר סיטוני וקמעוני; תיקון כלי רכב מנועיים ואופנועים | P14: 8465.3974 | Q14: 8367.4328 | R14: 9359.7986 | S14: 7686.4274 | T14: 7780.743 | U14: 11319.051 | V14: 7873.3292 | W14: 11905.127 | X14: 9094.6632
A15: איוש | B15: M | C15: =VLOOKUP(B15,רשויות_ענף_כלכלי__2ספרות_!$J$2:$L$115,3,FALSE) -> שירותים מקצועיים, מדעיים וטכניים | D15: 11439 | E15: 14131.38 | O15: פעילויות בנדל"ן | P15: 11552.952 | Q15: 10846.158 | R15: 12534.491 | S15: 11589.134 | T15: 9456.4944 | U15: 15996.555 | V15: 11414.499 | W15: 17234.842 | X15: 12578.141
... A22: איוש | B22: U | C22: =VLOOKUP(B22,רשויות_ענף_כלכלי__2ספרות_!$J$2:$L$115,3,FALSE) -> ארגונים וגופים חוץ-מדינתיים | D22: 61 | E22: 22218.944 | O22: שירותים פיננסיים ושירותי ביטוח | P22: 19166.415 | Q22: 16293.984 | R22: 17743.834 | S22: 19067.109 | T22: 14707.372 | U22: 22398.884 | V22: 14380.111 | W22: 24120.994 | X22: 18484.838
A23: דרום | B23: * | D23: 13904 | E23: 19219.745 | O23: תעשייה | P23: 15448.778 | Q23: 14445.404 | R23: 15981.593 | S23: 13431.295 | T23: 12463.32 | U23: 20192.498 | V23: 12236.243 | W23: 19887.932 | X23: 15510.883
A24: דרום | B24: A | C24: =VLOOKUP(B24,רשויות_ענף_כלכלי__2ספרות_!$J$2:$L$115,3,FALSE) -> חקלאות, ייעור ודיג | D24: 13728 | E24: 9298.6696 | O24: (blank) | P24: 20201.097 | X24: 20201.097
A25: דרום | B25: B | C25: =VLOOKUP(B25,רשויות_ענף_כלכלי__2ספרות_!$J$2:$L$115,3,FALSE) -> כרייה וחציבה | D25: 2525 | E25: 29879.927 | O25: Grand Total | P25: 13547.336 | Q25: 13181.671 | R25: 13693.31 | S25: 12187.323 | T25: 11985.561 | U25: 15780.878 | V25: 11646.207 | W25: 16527.072 | X25: 13568.67
A26: דרום | B26: C | C26: =VLOOKUP(B26,רשויות_ענף_כלכלי__2ספרות_!$J$2:$L$115,3,FALSE) -> תעשייה | D26: 67729 | E26: 14445.404
A27: דרום | B27: D | C27: =VLOOKUP(B27,רשויות_ענף_כלכלי__2ספרות_!$J$2:$L$115,3,FALSE) -> אספקת חשמל, גז, קיטור ומיזוג אוויר | D27: 2978 | E27: 25753.132
A28: דרום | B28: E | C28: =VLOOKUP(B28,רשויות_ענף_כלכלי__2ספרות_!$J$2:$L$115,3,FALSE) -> אספקת מים; שירותי ביוב, טיפול באשפה ובפסולת ושירותי טיהור | D28: 3238 | E28: 13878.68
A29: דרום | B29: F | C29: =VLOOKUP(B29,רשויות_ענף_כלכלי__2ספרות_!$J$2:$L$115,3,FALSE) -> בינוי | D29: 39531 | E29: 11371.466
A30: דרום | B30: G | C30: =VLOOKUP(B30,רשויות_ענף_כלכלי__2ספרות_!$J$2:$L$115,3,FALSE) -> מסחר סיטוני וקמעוני; תיקון כלי רכב מנועיים ואופנועים | D30: 82322 | E30: 8367.4328
A31: דרום | B31: H | C31: =VLOOKUP(B31,רשויות_ענף_כלכלי__2ספרות_!$J$2:$L$115,3,FALSE) -> שירותי תחבורה, אחסנה, דואר ובלדרות | D31: 30828 | E31: 11965.404
A32: דרום | B32: I | C32: =VLOOKUP(B32,רשויות_ענף_כלכלי__2ספרות_!$J$2:$L$115,3,FALSE) -> שירותי אירוח ואוכל | D32: 43533 | E32: 5947.2033
A33: דרום | B33: J | C33: =VLOOKUP(B33,רשויות_ענף_כלכלי__2ספרות_!$J$2:$L$115,3,FALSE) -> מידע ותקשורת | D33: 18009 | E33: 19665.653
A34: דרום | B34: K | C34: =VLOOKUP(B34,רשויות_ענף_כלכלי__2ספרות_!$J$2:$L$115,3,FALSE) -> שירותים פיננסיים ושירותי ביטוח | D34: 8958 | E34: 16293.984
A35: דרום | B35: L | C35: =VLOOKUP(B35,רשויות_ענף_כלכלי__2ספרות_!$J$2:$L$115,3,FALSE) -> פעילויות בנדל"ן | D35: 4115 | E35: 10846.158
A36: דרום | B36: M | C36: =VLOOKUP(B36,רשויות_ענף_כלכלי__2ספרות_!$J$2:$L$115,3,FALSE) -> שירותים מקצועיים, מדעיים וטכניים | D36: 27716 | E36: 12638.145
A37: דרום | B37: N | C37: =VLOOKUP(B37,רשויות_ענף_כלכלי__2ספרות_!$J$2:$L$115,3,FALSE) -> שירותי ניהול ותמיכה | D37: 57599 | E37: 6163.8218 | O37: Average of שכר חודשי ממוצי | P37: Column Labels
A38: דרום | B38: O | C38: =VLOOKUP(B38,רשויות_ענף_כלכלי__2ספרות_!$J$2:$L$115,3,FALSE) -> מינהל מקומי, מינהל ציבורי וביטחון; ביטוח לאומי חובה | D38: 36869 | E38: 11536.024 | O38: ענף כלכלי | P38: נפות צפת וגולן | Q38: ממוצע ארצי | R38: ממוצע שכר באשכול | S38: ממוצע שכר ארצי
A39: דרום | B39: P | C39: =VLOOKUP(B39,רשויות_ענף_כלכלי__2ספרות_!$J$2:$L$115,3,FALSE) -> חינוך | D39: 59122 | E39: 10663.385 | O39: אמנות, בידור ופנאי | P39: 6768.9293 | Q39: 6794.7197 | R39: =AVERAGE(P39:P58) -> 11551.916 | S39: =AVERAGE(Q39:Q58) -> 13515.114
A40: דרום | B40: Q | C40: =VLOOKUP(B40,רשויות_ענף_כלכלי__2ספרות_!$J$2:$L$115,3,FALSE) -> שירותי בריאות, רווחה וסעד | D40: 69621 | E40: 8269.8853 | O40: אספקת חשמל, גז, קיטור ומיזוג אוויר | P40: 22344.183 | Q40: 27517.288 | R40: 11551.916 | S40: 13515.114
A41: דרום | B41: R | C41: =VLOOKUP(B41,רשויות_ענף_כלכלי__2ספרות_!$J$2:$L$115,3,FALSE) -> אמנות, בידור ופנאי | D41: 8181 | E41: 7019.4053 | O41: אספקת מים; שירותי ביוב, טיפול באשפה ובפסולת ושירותי טיהור | P41: 15086.192 | Q41: 14015.041 | R41: 11551.916 | S41: 13515.114
A42: דרום | B42: S | C42: =VLOOKUP(B42,רשויות_ענף_כלכלי__2ספרות_!$J$2:$L$115,3,FALSE) -> שירותים אחרים | D42: 23730 | E42: 6143.1605 | O42: ארגונים וגופים חוץ-מדינתיים | P42: 13491.191 | Q42: 17773.102 | R42: 11551.916 | S42: 13515.114
A43: דרום | B43: U | C43: =VLOOKUP(B43,רשויות_ענף_כלכלי__2ספרות_!$J$2:$L$115,3,FALSE) -> ארגונים וגופים חוץ-מדינתיים | D43: 46 | E43: 17448.402 | O43: בינוי | P43: 8594.0469 | Q43: 11320.915 | R43: 11551.916 | S43: 13515.114
A44: חיפה | B44: * | D44: 14820 | E44: 19856.794 | O44: חינוך | P44: 10469.979 | Q44: 10293.101 | R44: 11551.916 | S44: 13515.114
A45: חיפה | B45: A | C45: =VLOOKUP(B45,רשויות_ענף_כלכלי__2ספרות_!$J$2:$L$115,3,FALSE) -> חקלאות, ייעור ודיג | D45: 6338 | E45: 8493.061 | O45: חקלאות, ייעור ודיג | P45: 13532.036 | Q45: 13845.314 | R45: 11551.916 | S45: 13515.114
A46: חיפה | B46: B | C46: =VLOOKUP(B46,רשויות_ענף_כלכלי__2ספרות_!$J$2:$L$115,3,FALSE) -> כרייה וחציבה | D46: 409 | E46: 21114.719 | O46: כרייה וחציבה | P46: 17832.677 | Q46: 23360.192 | R46: 11551.916 | S46: 13515.114
...
